Traceback (most recent call last):
  File "/home/bvextp1/.local/lib/python3.9/site-packages/adafruit_bus_device/i2c_device.py", line 176, in __probe_for_device
    self.i2c.writeto(self.device_address, b"")
  File "/home/bvextp1/.local/lib/python3.9/site-packages/busio.py", line 196, in writeto
    return self._i2c.writeto(address, buffer, stop=stop)
  File "/home/bvextp1/.local/lib/python3.9/site-packages/adafruit_blinka/microcontroller/generic_linux/i2c.py", line 52, in writeto
    self._i2c_bus.write_bytes(address, buffer[start:end])
  File "/home/bvextp1/.local/lib/python3.9/site-packages/Adafruit_PureIO/smbus.py", line 320, in write_bytes
    self._device.write(buf)
OSError: [Errno 121] Remote I/O error

During handling of the above exception, another exception occurred:

Traceback (most recent call last):
  File "/home/bvextp1/.local/lib/python3.9/site-packages/adafruit_bus_device/i2c_device.py", line 182, in __probe_for_device
    self.i2c.readfrom_into(self.device_address, result)
  File "/home/bvextp1/.local/lib/python3.9/site-packages/busio.py", line 186, in readfrom_into
    return self._i2c.readfrom_into(address, buffer, stop=stop)
  File "/home/bvextp1/.local/lib/python3.9/site-packages/adafruit_blinka/microcontroller/generic_linux/i2c.py", line 59, in readfrom_into
    readin = self._i2c_bus.read_bytes(address, end - start)
  File "/home/bvextp1/.local/lib/python3.9/site-packages/Adafruit_PureIO/smbus.py", line 187, in read_bytes
    return self._device.read(number)
OSError: [Errno 121] Remote I/O error

During handling of the above exception, another exception occurred:

Traceback (most recent call last):
  File "/home/bvextp1/Magnetometer/Magnetometer.py", line 11, in <module>
    sensor = LIS3MDL(i2c)
  File "/home/bvextp1/.local/lib/python3.9/site-packages/adafruit_lis3mdl.py", line 233, in __init__
    self.i2c_device = i2c_device.I2CDevice(i2c_bus, address)
  File "/home/bvextp1/.local/lib/python3.9/site-packages/adafruit_bus_device/i2c_device.py", line 63, in __init__
    self.__probe_for_device()
  File "/home/bvextp1/.local/lib/python3.9/site-packages/adafruit_bus_device/i2c_device.py", line 185, in __probe_for_device
    raise ValueError("No I2C device at address: 0x%x" % self.device_address)
ValueError: No I2C device at address: 0x1c
